2025-09-20 10:16:55 - ai_model - ERROR - clip 模型初始化失败: Failed to download weights for tag 'laion2b_s34b_b79k': Failed to download file (open_clip_pytorch_model.bin) for laion/CLIP-ViT-B-32-laion2B-s34B-b79K. Last error: An error happened while trying to locate the file on the Hub and we cannot find the requested files in the local cache. Please check your connection and try again or make sure your Internet connection is on.
2025-09-20 10:16:55 - ai_model - ERROR - Traceback (most recent call last):
  File "C:\Users\An\AppData\Roaming\Python\Python313\site-packages\urllib3\connection.py", line 198, in _new_conn
    sock = connection.create_connection(
        (self._dns_host, self.port),
    ...<2 lines>...
        socket_options=self.socket_options,
    )
  File "C:\Users\An\AppData\Roaming\Python\Python313\site-packages\urllib3\util\connection.py", line 85, in create_connection
    raise err
  File "C:\Users\An\AppData\Roaming\Python\Python313\site-packages\urllib3\util\connection.py", line 73, in create_connection
    sock.connect(sa)
    ~~~~~~~~~~~~^^^^
TimeoutError: timed out

The above exception was the direct cause of the following exception:

Traceback (most recent call last):
  File "C:\Users\An\AppData\Roaming\Python\Python313\site-packages\urllib3\connectionpool.py", line 787, in urlopen
    response = self._make_request(
        conn,
    ...<10 lines>...
        **response_kw,
    )
  File "C:\Users\An\AppData\Roaming\Python\Python313\site-packages\urllib3\connectionpool.py", line 488, in _make_request
    raise new_e
  File "C:\Users\An\AppData\Roaming\Python\Python313\site-packages\urllib3\connectionpool.py", line 464, in _make_request
    self._validate_conn(conn)
    ~~~~~~~~~~~~~~~~~~~^^^^^^
  File "C:\Users\An\AppData\Roaming\Python\Python313\site-packages\urllib3\connectionpool.py", line 1093, in _validate_conn
    conn.connect()
    ~~~~~~~~~~~~^^
  File "C:\Users\An\AppData\Roaming\Python\Python313\site-packages\urllib3\connection.py", line 753, in connect
    self.sock = sock = self._new_conn()
                       ~~~~~~~~~~~~~~^^
  File "C:\Users\An\AppData\Roaming\Python\Python313\site-packages\urllib3\connection.py", line 207, in _new_conn
    raise ConnectTimeoutError(
    ...<2 lines>...
    ) from e
urllib3.exceptions.ConnectTimeoutError: (<urllib3.connection.HTTPSConnection object at 0x0000023AB905AD50>, 'Connection to huggingface.co timed out. (connect timeout=10)')

The above exception was the direct cause of the following exception:

Traceback (most recent call last):
  File "C:\Users\An\AppData\Roaming\Python\Python313\site-packages\requests\adapters.py", line 667, in send
    resp = conn.urlopen(
        method=request.method,
    ...<9 lines>...
        chunked=chunked,
    )
  File "C:\Users\An\AppData\Roaming\Python\Python313\site-packages\urllib3\connectionpool.py", line 841, in urlopen
    retries = retries.increment(
        method, url, error=new_e, _pool=self, _stacktrace=sys.exc_info()[2]
    )
  File "C:\Users\An\AppData\Roaming\Python\Python313\site-packages\urllib3\util\retry.py", line 519, in increment
    raise MaxRetryError(_pool, url, reason) from reason  # type: ignore[arg-type]
    ^^^^^^^^^^^^^^^^^^^^^^^^^^^^^^^^^^^^^^^^^^^^^^^^^^^
urllib3.exceptions.MaxRetryError: HTTPSConnectionPool(host='huggingface.co', port=443): Max retries exceeded with url: /laion/CLIP-ViT-B-32-laion2B-s34B-b79K/resolve/main/open_clip_pytorch_model.bin (Caused by ConnectTimeoutError(<urllib3.connection.HTTPSConnection object at 0x0000023AB905AD50>, 'Connection to huggingface.co timed out. (connect timeout=10)'))

During handling of the above exception, another exception occurred:

Traceback (most recent call last):
  File "C:\Users\An\AppData\Roaming\Python\Python313\site-packages\huggingface_hub\file_download.py", line 1546, in _get_metadata_or_catch_error
    metadata = get_hf_file_metadata(
        url=url, proxies=proxies, timeout=etag_timeout, headers=headers, token=token, endpoint=endpoint
    )
  File "C:\Users\An\AppData\Roaming\Python\Python313\site-packages\huggingface_hub\utils\_validators.py", line 114, in _inner_fn
    return fn(*args, **kwargs)
  File "C:\Users\An\AppData\Roaming\Python\Python313\site-packages\huggingface_hub\file_download.py", line 1463, in get_hf_file_metadata
    r = _request_wrapper(
        method="HEAD",
    ...<5 lines>...
        timeout=timeout,
    )
  File "C:\Users\An\AppData\Roaming\Python\Python313\site-packages\huggingface_hub\file_download.py", line 286, in _request_wrapper
    response = _request_wrapper(
        method=method,
    ...<2 lines>...
        **params,
    )
  File "C:\Users\An\AppData\Roaming\Python\Python313\site-packages\huggingface_hub\file_download.py", line 309, in _request_wrapper
    response = http_backoff(method=method, url=url, **params, retry_on_exceptions=(), retry_on_status_codes=(429,))
  File "C:\Users\An\AppData\Roaming\Python\Python313\site-packages\huggingface_hub\utils\_http.py", line 310, in http_backoff
    response = session.request(method=method, url=url, **kwargs)
  File "C:\Users\An\AppData\Roaming\Python\Python313\site-packages\requests\sessions.py", line 589, in request
    resp = self.send(prep, **send_kwargs)
  File "C:\Users\An\AppData\Roaming\Python\Python313\site-packages\requests\sessions.py", line 703, in send
    r = adapter.send(request, **kwargs)
  File "C:\Users\An\AppData\Roaming\Python\Python313\site-packages\huggingface_hub\utils\_http.py", line 96, in send
    return super().send(request, *args, **kwargs)
           ~~~~~~~~~~~~^^^^^^^^^^^^^^^^^^^^^^^^^^
  File "C:\Users\An\AppData\Roaming\Python\Python313\site-packages\requests\adapters.py", line 688, in send
    raise ConnectTimeout(e, request=request)
requests.exceptions.ConnectTimeout: (MaxRetryError("HTTPSConnectionPool(host='huggingface.co', port=443): Max retries exceeded with url: /laion/CLIP-ViT-B-32-laion2B-s34B-b79K/resolve/main/open_clip_pytorch_model.bin (Caused by ConnectTimeoutError(<urllib3.connection.HTTPSConnection object at 0x0000023AB905AD50>, 'Connection to huggingface.co timed out. (connect timeout=10)'))"), '(Request ID: 9d693f81-5776-4d00-82d2-4e9ee6e92403)')

The above exception was the direct cause of the following exception:

Traceback (most recent call last):
  File "C:\Users\An\AppData\Roaming\Python\Python313\site-packages\open_clip\pretrained.py", line 869, in download_pretrained_from_hf
    cached_file = hf_hub_download(
        repo_id=model_id,
    ...<2 lines>...
        cache_dir=cache_dir,
    )
  File "C:\Users\An\AppData\Roaming\Python\Python313\site-packages\huggingface_hub\utils\_validators.py", line 114, in _inner_fn
    return fn(*args, **kwargs)
  File "C:\Users\An\AppData\Roaming\Python\Python313\site-packages\huggingface_hub\file_download.py", line 1010, in hf_hub_download
    return _hf_hub_download_to_cache_dir(
        # Destination
    ...<14 lines>...
        force_download=force_download,
    )
  File "C:\Users\An\AppData\Roaming\Python\Python313\site-packages\huggingface_hub\file_download.py", line 1117, in _hf_hub_download_to_cache_dir
    _raise_on_head_call_error(head_call_error, force_download, local_files_only)
    ~~~~~~~~~~~~~~~~~~~~~~~~~^^^^^^^^^^^^^^^^^^^^^^^^^^^^^^^^^^^^^^^^^^^^^^^^^^^
  File "C:\Users\An\AppData\Roaming\Python\Python313\site-packages\huggingface_hub\file_download.py", line 1661, in _raise_on_head_call_error
    raise LocalEntryNotFoundError(
    ...<3 lines>...
    ) from head_call_error
huggingface_hub.errors.LocalEntryNotFoundError: An error happened while trying to locate the file on the Hub and we cannot find the requested files in the local cache. Please check your connection and try again or make sure your Internet connection is on.

During handling of the above exception, another exception occurred:

Traceback (most recent call last):
  File "C:\Users\An\AppData\Roaming\Python\Python313\site-packages\open_clip\factory.py", line 412, in create_model
    checkpoint_path = download_pretrained(pretrained_cfg_for_tag, cache_dir=cache_dir)
  File "C:\Users\An\AppData\Roaming\Python\Python313\site-packages\open_clip\pretrained.py", line 910, in download_pretrained
    target = download_pretrained_from_hf(model_id, cache_dir=cache_dir)
  File "C:\Users\An\AppData\Roaming\Python\Python313\site-packages\open_clip\pretrained.py", line 877, in download_pretrained_from_hf
    raise FileNotFoundError(f"Failed to download file ({filename}) for {model_id}. Last error: {e}")
FileNotFoundError: Failed to download file (open_clip_pytorch_model.bin) for laion/CLIP-ViT-B-32-laion2B-s34B-b79K. Last error: An error happened while trying to locate the file on the Hub and we cannot find the requested files in the local cache. Please check your connection and try again or make sure your Internet connection is on.

During handling of the above exception, another exception occurred:

Traceback (most recent call last):
  File "D:\新建文件夹\OneDrive\桌面\python file\智能体爬虫\agent\ai_model.py", line 47, in initialize_model
    self._init_clip_model()
    ~~~~~~~~~~~~~~~~~~~~~^^
  File "D:\新建文件夹\OneDrive\桌面\python file\智能体爬虫\agent\ai_model.py", line 66, in _init_clip_model
    self.model, _, self.preprocess = open_clip.create_model_and_transforms('ViT-B-32', pretrained='laion2b_s34b_b79k')
                                     ~~~~~~~~~~~~~~~~~~~~~~~~~~~~~~~~~~~~~^^^^^^^^^^^^^^^^^^^^^^^^^^^^^^^^^^^^^^^^^^^^
  File "C:\Users\An\AppData\Roaming\Python\Python313\site-packages\open_clip\factory.py", line 930, in create_model_and_transforms
    model = create_model(
        model_name,
    ...<18 lines>...
        **model_kwargs,
    )
  File "C:\Users\An\AppData\Roaming\Python\Python313\site-packages\open_clip\factory.py", line 417, in create_model
    raise RuntimeError(f"Failed to download weights for tag '{pretrained}': {e}")
RuntimeError: Failed to download weights for tag 'laion2b_s34b_b79k': Failed to download file (open_clip_pytorch_model.bin) for laion/CLIP-ViT-B-32-laion2B-s34B-b79K. Last error: An error happened while trying to locate the file on the Hub and we cannot find the requested files in the local cache. Please check your connection and try again or make sure your Internet connection is on.

2025-09-20 11:11:25 - ai_model - ERROR - clip 模型初始化失败: Failed to download weights for tag 'laion2b_s34b_b79k': Failed to download file (open_clip_pytorch_model.bin) for laion/CLIP-ViT-B-32-laion2B-s34B-b79K. Last error: An error happened while trying to locate the file on the Hub and we cannot find the requested files in the local cache. Please check your connection and try again or make sure your Internet connection is on.
2025-09-20 11:11:25 - ai_model - ERROR - Traceback (most recent call last):
  File "C:\Users\An\AppData\Roaming\Python\Python313\site-packages\urllib3\connection.py", line 198, in _new_conn
    sock = connection.create_connection(
        (self._dns_host, self.port),
    ...<2 lines>...
        socket_options=self.socket_options,
    )
  File "C:\Users\An\AppData\Roaming\Python\Python313\site-packages\urllib3\util\connection.py", line 85, in create_connection
    raise err
  File "C:\Users\An\AppData\Roaming\Python\Python313\site-packages\urllib3\util\connection.py", line 73, in create_connection
    sock.connect(sa)
    ~~~~~~~~~~~~^^^^
TimeoutError: timed out

The above exception was the direct cause of the following exception:

Traceback (most recent call last):
  File "C:\Users\An\AppData\Roaming\Python\Python313\site-packages\urllib3\connectionpool.py", line 787, in urlopen
    response = self._make_request(
        conn,
    ...<10 lines>...
        **response_kw,
    )
  File "C:\Users\An\AppData\Roaming\Python\Python313\site-packages\urllib3\connectionpool.py", line 488, in _make_request
    raise new_e
  File "C:\Users\An\AppData\Roaming\Python\Python313\site-packages\urllib3\connectionpool.py", line 464, in _make_request
    self._validate_conn(conn)
    ~~~~~~~~~~~~~~~~~~~^^^^^^
  File "C:\Users\An\AppData\Roaming\Python\Python313\site-packages\urllib3\connectionpool.py", line 1093, in _validate_conn
    conn.connect()
    ~~~~~~~~~~~~^^
  File "C:\Users\An\AppData\Roaming\Python\Python313\site-packages\urllib3\connection.py", line 753, in connect
    self.sock = sock = self._new_conn()
                       ~~~~~~~~~~~~~~^^
  File "C:\Users\An\AppData\Roaming\Python\Python313\site-packages\urllib3\connection.py", line 207, in _new_conn
    raise ConnectTimeoutError(
    ...<2 lines>...
    ) from e
urllib3.exceptions.ConnectTimeoutError: (<urllib3.connection.HTTPSConnection object at 0x000002D3C1B9C7D0>, 'Connection to huggingface.co timed out. (connect timeout=10)')

The above exception was the direct cause of the following exception:

Traceback (most recent call last):
  File "C:\Users\An\AppData\Roaming\Python\Python313\site-packages\requests\adapters.py", line 667, in send
    resp = conn.urlopen(
        method=request.method,
    ...<9 lines>...
        chunked=chunked,
    )
  File "C:\Users\An\AppData\Roaming\Python\Python313\site-packages\urllib3\connectionpool.py", line 841, in urlopen
    retries = retries.increment(
        method, url, error=new_e, _pool=self, _stacktrace=sys.exc_info()[2]
    )
  File "C:\Users\An\AppData\Roaming\Python\Python313\site-packages\urllib3\util\retry.py", line 519, in increment
    raise MaxRetryError(_pool, url, reason) from reason  # type: ignore[arg-type]
    ^^^^^^^^^^^^^^^^^^^^^^^^^^^^^^^^^^^^^^^^^^^^^^^^^^^
urllib3.exceptions.MaxRetryError: HTTPSConnectionPool(host='huggingface.co', port=443): Max retries exceeded with url: /laion/CLIP-ViT-B-32-laion2B-s34B-b79K/resolve/main/open_clip_pytorch_model.bin (Caused by ConnectTimeoutError(<urllib3.connection.HTTPSConnection object at 0x000002D3C1B9C7D0>, 'Connection to huggingface.co timed out. (connect timeout=10)'))

During handling of the above exception, another exception occurred:

Traceback (most recent call last):
  File "C:\Users\An\AppData\Roaming\Python\Python313\site-packages\huggingface_hub\file_download.py", line 1546, in _get_metadata_or_catch_error
    metadata = get_hf_file_metadata(
        url=url, proxies=proxies, timeout=etag_timeout, headers=headers, token=token, endpoint=endpoint
    )
  File "C:\Users\An\AppData\Roaming\Python\Python313\site-packages\huggingface_hub\utils\_validators.py", line 114, in _inner_fn
    return fn(*args, **kwargs)
  File "C:\Users\An\AppData\Roaming\Python\Python313\site-packages\huggingface_hub\file_download.py", line 1463, in get_hf_file_metadata
    r = _request_wrapper(
        method="HEAD",
    ...<5 lines>...
        timeout=timeout,
    )
  File "C:\Users\An\AppData\Roaming\Python\Python313\site-packages\huggingface_hub\file_download.py", line 286, in _request_wrapper
    response = _request_wrapper(
        method=method,
    ...<2 lines>...
        **params,
    )
  File "C:\Users\An\AppData\Roaming\Python\Python313\site-packages\huggingface_hub\file_download.py", line 309, in _request_wrapper
    response = http_backoff(method=method, url=url, **params, retry_on_exceptions=(), retry_on_status_codes=(429,))
  File "C:\Users\An\AppData\Roaming\Python\Python313\site-packages\huggingface_hub\utils\_http.py", line 310, in http_backoff
    response = session.request(method=method, url=url, **kwargs)
  File "C:\Users\An\AppData\Roaming\Python\Python313\site-packages\requests\sessions.py", line 589, in request
    resp = self.send(prep, **send_kwargs)
  File "C:\Users\An\AppData\Roaming\Python\Python313\site-packages\requests\sessions.py", line 703, in send
    r = adapter.send(request, **kwargs)
  File "C:\Users\An\AppData\Roaming\Python\Python313\site-packages\huggingface_hub\utils\_http.py", line 96, in send
    return super().send(request, *args, **kwargs)
           ~~~~~~~~~~~~^^^^^^^^^^^^^^^^^^^^^^^^^^
  File "C:\Users\An\AppData\Roaming\Python\Python313\site-packages\requests\adapters.py", line 688, in send
    raise ConnectTimeout(e, request=request)
requests.exceptions.ConnectTimeout: (MaxRetryError("HTTPSConnectionPool(host='huggingface.co', port=443): Max retries exceeded with url: /laion/CLIP-ViT-B-32-laion2B-s34B-b79K/resolve/main/open_clip_pytorch_model.bin (Caused by ConnectTimeoutError(<urllib3.connection.HTTPSConnection object at 0x000002D3C1B9C7D0>, 'Connection to huggingface.co timed out. (connect timeout=10)'))"), '(Request ID: b3cb5247-7d23-4867-aca5-389ceb51bc7d)')

The above exception was the direct cause of the following exception:

Traceback (most recent call last):
  File "C:\Users\An\AppData\Roaming\Python\Python313\site-packages\open_clip\pretrained.py", line 869, in download_pretrained_from_hf
    cached_file = hf_hub_download(
        repo_id=model_id,
    ...<2 lines>...
        cache_dir=cache_dir,
    )
  File "C:\Users\An\AppData\Roaming\Python\Python313\site-packages\huggingface_hub\utils\_validators.py", line 114, in _inner_fn
    return fn(*args, **kwargs)
  File "C:\Users\An\AppData\Roaming\Python\Python313\site-packages\huggingface_hub\file_download.py", line 1010, in hf_hub_download
    return _hf_hub_download_to_cache_dir(
        # Destination
    ...<14 lines>...
        force_download=force_download,
    )
  File "C:\Users\An\AppData\Roaming\Python\Python313\site-packages\huggingface_hub\file_download.py", line 1117, in _hf_hub_download_to_cache_dir
    _raise_on_head_call_error(head_call_error, force_download, local_files_only)
    ~~~~~~~~~~~~~~~~~~~~~~~~~^^^^^^^^^^^^^^^^^^^^^^^^^^^^^^^^^^^^^^^^^^^^^^^^^^^
  File "C:\Users\An\AppData\Roaming\Python\Python313\site-packages\huggingface_hub\file_download.py", line 1661, in _raise_on_head_call_error
    raise LocalEntryNotFoundError(
    ...<3 lines>...
    ) from head_call_error
huggingface_hub.errors.LocalEntryNotFoundError: An error happened while trying to locate the file on the Hub and we cannot find the requested files in the local cache. Please check your connection and try again or make sure your Internet connection is on.

During handling of the above exception, another exception occurred:

Traceback (most recent call last):
  File "C:\Users\An\AppData\Roaming\Python\Python313\site-packages\open_clip\factory.py", line 412, in create_model
    checkpoint_path = download_pretrained(pretrained_cfg_for_tag, cache_dir=cache_dir)
  File "C:\Users\An\AppData\Roaming\Python\Python313\site-packages\open_clip\pretrained.py", line 910, in download_pretrained
    target = download_pretrained_from_hf(model_id, cache_dir=cache_dir)
  File "C:\Users\An\AppData\Roaming\Python\Python313\site-packages\open_clip\pretrained.py", line 877, in download_pretrained_from_hf
    raise FileNotFoundError(f"Failed to download file ({filename}) for {model_id}. Last error: {e}")
FileNotFoundError: Failed to download file (open_clip_pytorch_model.bin) for laion/CLIP-ViT-B-32-laion2B-s34B-b79K. Last error: An error happened while trying to locate the file on the Hub and we cannot find the requested files in the local cache. Please check your connection and try again or make sure your Internet connection is on.

During handling of the above exception, another exception occurred:

Traceback (most recent call last):
  File "D:\新建文件夹\OneDrive\桌面\python file\智能体爬虫\agent\ai_model.py", line 47, in initialize_model
    self._init_clip_model()
    ~~~~~~~~~~~~~~~~~~~~~^^
  File "D:\新建文件夹\OneDrive\桌面\python file\智能体爬虫\agent\ai_model.py", line 66, in _init_clip_model
    self.model, _, self.preprocess = open_clip.create_model_and_transforms('ViT-B-32', pretrained='laion2b_s34b_b79k')
                                     ~~~~~~~~~~~~~~~~~~~~~~~~~~~~~~~~~~~~~^^^^^^^^^^^^^^^^^^^^^^^^^^^^^^^^^^^^^^^^^^^^
  File "C:\Users\An\AppData\Roaming\Python\Python313\site-packages\open_clip\factory.py", line 930, in create_model_and_transforms
    model = create_model(
        model_name,
    ...<18 lines>...
        **model_kwargs,
    )
  File "C:\Users\An\AppData\Roaming\Python\Python313\site-packages\open_clip\factory.py", line 417, in create_model
    raise RuntimeError(f"Failed to download weights for tag '{pretrained}': {e}")
RuntimeError: Failed to download weights for tag 'laion2b_s34b_b79k': Failed to download file (open_clip_pytorch_model.bin) for laion/CLIP-ViT-B-32-laion2B-s34B-b79K. Last error: An error happened while trying to locate the file on the Hub and we cannot find the requested files in the local cache. Please check your connection and try again or make sure your Internet connection is on.

2025-09-20 21:28:46 - ai_model - WARNING - OpenCLIP库加载失败: Failed to download weights for tag 'laion2b_s34b_b79k': Failed to download file (open_clip_pytorch_model.bin) for laion/CLIP-ViT-B-32-laion2B-s34B-b79K. Last error: An error happened while trying to locate the file on the Hub and we cannot find the requested files in the local cache. Please check your connection and try again or make sure your Internet connection is on.
2025-09-20 21:28:46 - ai_model - INFO - 尝试使用transformers库加载CLIP模型
2025-09-20 21:29:06 - ai_model - WARNING - transformers库加载CLIP模型失败: We couldn't connect to 'https://huggingface.co' to load the files, and couldn't find them in the cached files.
Check your internet connection or see how to run the library in offline mode at 'https://huggingface.co/docs/transformers/installation#offline-mode'.
2025-09-20 21:29:06 - ai_model - WARNING - 无法加载真实模型，正在初始化模拟模型
2025-09-20 21:29:06 - ai_model - WARNING - 使用模拟CLIP模型，所有结果为示例数据
2025-09-20 21:29:06 - ai_model - INFO - 
===== 模型加载建议 =====
2025-09-20 21:29:06 - ai_model - INFO - 1. 检查网络连接，确保能访问 huggingface.co
2025-09-20 21:29:06 - ai_model - INFO - 2. 如果网络受限，可以手动下载模型权重并设置环境变量 CLIP_MODEL_PATH
2025-09-20 21:29:06 - ai_model - INFO - 3. 模拟模型仅用于演示，不提供真实的AI分析能力
2025-09-20 21:29:06 - ai_model - INFO - ========================

2025-09-20 21:29:06 - ai_model - WARNING - clip 模拟模型已初始化
2025-09-20 21:29:06 - ai_model - INFO - 使用模拟模型进行classification任务分析
2025-09-20 21:29:06 - ai_model - INFO - 使用模拟模型进行similarity任务分析
2025-09-20 21:29:06 - ai_model - INFO - 使用模拟模型进行captioning任务分析
2025-09-21 16:44:46 - ai_model - WARNING - OpenCLIP库加载失败: Failed to download weights for tag 'laion2b_s34b_b79k': Failed to download file (open_clip_pytorch_model.bin) for laion/CLIP-ViT-B-32-laion2B-s34B-b79K. Last error: An error happened while trying to locate the file on the Hub and we cannot find the requested files in the local cache. Please check your connection and try again or make sure your Internet connection is on.
2025-09-21 16:44:46 - ai_model - INFO - 尝试使用transformers库加载CLIP模型
2025-09-21 16:47:39 - ai_model - WARNING - OpenCLIP库加载失败: Failed to download weights for tag 'laion2b_s34b_b79k': Failed to download file (open_clip_pytorch_model.bin) for laion/CLIP-ViT-B-32-laion2B-s34B-b79K. Last error: An error happened while trying to locate the file on the Hub and we cannot find the requested files in the local cache. Please check your connection and try again or make sure your Internet connection is on.
2025-09-21 16:47:39 - ai_model - INFO - 尝试使用transformers库加载CLIP模型
2025-09-21 16:47:46 - ai_model - WARNING - OpenCLIP库加载失败: Failed to download weights for tag 'laion2b_s34b_b79k': Failed to download file (open_clip_pytorch_model.bin) for laion/CLIP-ViT-B-32-laion2B-s34B-b79K. Last error: An error happened while trying to locate the file on the Hub and we cannot find the requested files in the local cache. Please check your connection and try again or make sure your Internet connection is on.
2025-09-21 16:47:46 - ai_model - INFO - 尝试使用transformers库加载CLIP模型
2025-09-21 16:51:12 - ai_model - WARNING - OpenCLIP库加载失败: Failed to download weights for tag 'laion2b_s34b_b79k': Failed to download file (open_clip_pytorch_model.bin) for laion/CLIP-ViT-B-32-laion2B-s34B-b79K. Last error: An error happened while trying to locate the file on the Hub and we cannot find the requested files in the local cache. Please check your connection and try again or make sure your Internet connection is on.
2025-09-21 16:51:12 - ai_model - INFO - 尝试使用transformers库加载CLIP模型
